Workbook

Sheet CBA Digital Banking Case Study 
A1: customer_id | B1: age | C1: income | D1: region | E1: total_balance | F1: num_products | G1: monthly_transactions | H1: digital_logins_month | I1: preferred_channel | J1: product_interest_score | K1: churn_risk_score | L1: QUARTILE | M1: Preferred Channel | N1: Age Bucket | O1: Income Bucket
A2: 100000 | B2: 56 | C2: 25000 | D2: WA | E2: 47556.32 | F2: 2 | G2: 23 | H2: 2 | I2: Branch | J2: 0.191 | K2: 0.677 | L2: =if(J2>QUARTILE!$B$3, "TOP", if(J2<QUARTILE!$B$4, "BOTTOM", 0)) -> BOTTOM | M2: =if(I2="branch", 1, if(I2="Internet", 2, 3)) -> 1 | N2: =if(B2<16, "Gen Z", if(B2<31, "Millenial", if(B2<61, "Gen X", if(B2<80, "Baby Boomer", "Silent")))) -> Gen X | O2: =if(C2<45000, "Low Income", if(C2<135000, "Medium Income", if(C2<190000, "High Income", "Highest Income"))) -> Low Income
A3: 100001 | B3: 69 | C3: 24000 | D3: SA | E3: 6129.6 | F3: 2 | G3: 26 | H3: 4 | I3: Internet | J3: 0.909 | K3: 0.711 | L3: =if(J3>QUARTILE!$B$3, "TOP", if(J3<QUARTILE!$B$4, "BOTTOM", 0)) -> TOP | M3: =if(I3="branch", 1, if(I3="Internet", 2, 3)) -> 2 | N3: =if(B3<16, "Gen Z", if(B3<31, "Millenial", if(B3<61, "Gen X", if(B3<80, "Baby Boomer", "Silent")))) -> Baby Boomer | O3: =if(C3<45000, "Low Income", if(C3<135000, "Medium Income", if(C3<190000, "High Income", "Highest Income"))) -> Low Income
A4: 100002 | B4: 46 | C4: 15000 | D4: NSW | E4: 6597.25 | F4: 2 | G4: 15 | H4: 8 | I4: Internet | J4: 0.824 | K4: 0.551 | L4: =if(J4>QUARTILE!$B$3, "TOP", if(J4<QUARTILE!$B$4, "BOTTOM", 0)) -> TOP | M4: =if(I4="branch", 1, if(I4="Internet", 2, 3)) -> 2 | N4: =if(B4<16, "Gen Z", if(B4<31, "Millenial", if(B4<61, "Gen X", if(B4<80, "Baby Boomer", "Silent")))) -> Gen X | O4: =if(C4<45000, "Low Income", if(C4<135000, "Medium Income", if(C4<190000, "High Income", "Highest Income"))) -> Low Income
A5: 100003 | B5: 32 | C5: 27000 | D5: WA | E5: 10653 | F5: 2 | G5: 24 | H5: 5 | I5: Internet | J5: 0.552 | K5: 0.889 | L5: =if(J5>QUARTILE!$B$3, "TOP", if(J5<QUARTILE!$B$4, "BOTTOM", 0)) -> 0 | M5: =if(I5="branch", 1, if(I5="Internet", 2, 3)) -> 2 | N5: =if(B5<16, "Gen Z", if(B5<31, "Millenial", if(B5<61, "Gen X", if(B5<80, "Baby Boomer", "Silent")))) -> Gen X | O5: =if(C5<45000, "Low Income", if(C5<135000, "Medium Income", if(C5<190000, "High Income", "Highest Income"))) -> Low Income
A6: 100004 | B6: 60 | C6: 55000 | D6: TAS | E6: 3003.4 | F6: 3 | G6: 21 | H6: 2 | I6: Internet | J6: 0.565 | K6: 0.346 | L6: =if(J6>QUARTILE!$B$3, "TOP", if(J6<QUARTILE!$B$4, "BOTTOM", 0)) -> 0 | M6: =if(I6="branch", 1, if(I6="Internet", 2, 3)) -> 2 | N6: =if(B6<16, "Gen Z", if(B6<31, "Millenial", if(B6<61, "Gen X", if(B6<80, "Baby Boomer", "Silent")))) -> Gen X | O6: =if(C6<45000, "Low Income", if(C6<135000, "Medium Income", if(C6<190000, "High Income", "Highest Income"))) -> Medium Income
A7: 100005 | B7: 25 | C7: 15000 | D7: TAS | E7: 14155.99 | F7: 5 | G7: 17 | H7: 12 | I7: Branch | J7: 0.468 | K7: 0.008 | L7: =if(J7>QUARTILE!$B$3, "TOP", if(J7<QUARTILE!$B$4, "BOTTOM", 0)) -> 0 | M7: =if(I7="branch", 1, if(I7="Internet", 2, 3)) -> 1 | N7: =if(B7<16, "Gen Z", if(B7<31, "Millenial", if(B7<61, "Gen X", if(B7<80, "Baby Boomer", "Silent")))) -> Millenial | O7: =if(C7<45000, "Low Income", if(C7<135000, "Medium Income", if(C7<190000, "High Income", "Highest Income"))) -> Low Income
A8: 100006 | B8: 78 | C8: 39000 | D8: SA | E8: 21874.39 | F8: 2 | G8: 18 | H8: 5 | I8: Internet | J8: 0.616 | K8: 0.376 | L8: =if(J8>QUARTILE!$B$3, "TOP", if(J8<QUARTILE!$B$4, "BOTTOM", 0)) -> 0 | M8: =if(I8="branch", 1, if(I8="Internet", 2, 3)) -> 2 | N8: =if(B8<16, "Gen Z", if(B8<31, "Millenial", if(B8<61, "Gen X", if(B8<80, "Baby Boomer", "Silent")))) -> Baby Boomer | O8: =if(C8<45000, "Low Income", if(C8<135000, "Medium Income", if(C8<190000, "High Income", "Highest Income"))) -> Low Income
A9: 100007 | B9: 38 | C9: 11000 | D9: VIC | E9: 30835.63 | F9: 2 | G9: 16 | H9: 6 | I9: Branch | J9: 0.695 | K9: 0.775 | L9: =if(J9>QUARTILE!$B$3, "TOP", if(J9<QUARTILE!$B$4, "BOTTOM", 0)) -> 0 | M9: =if(I9="branch", 1, if(I9="Internet", 2, 3)) -> 1 | N9: =if(B9<16, "Gen Z", if(B9<31, "Millenial", if(B9<61, "Gen X", if(B9<80, "Baby Boomer", "Silent")))) -> Gen X | O9: =if(C9<45000, "Low Income", if(C9<135000, "Medium Income", if(C9<190000, "High Income", "Highest Income"))) -> Low Income
A10: 100008 | B10: 56 | C10: 78000 | D10: VIC | E10: 24858.03 | F10: 2 | G10: 14 | H10: 5 | I10: Internet | J10: 0.632 | K10: 0.077 | L10: =if(J10>QUARTILE!$B$3, "TOP", if(J10<QUARTILE!$B$4, "BOTTOM", 0)) -> 0 | M10: =if(I10="branch", 1, if(I10="Internet", 2, 3)) -> 2 | N10: =if(B10<16, "Gen Z", if(B10<31, "Millenial", if(B10<61, "Gen X", if(B10<80, "Baby Boomer", "Silent")))) -> Gen X | O10: =if(C10<45000, "Low Income", if(C10<135000, "Medium Income", if(C10<190000, "High Income", "Highest Income"))) -> Medium Income
A11: 100009 | B11: 75 | C11: 35000 | D11: NSW | E11: 3194.83 | F11: 5 | G11: 17 | H11: 2 | I11: Internet | J11: 0.729 | K11: 0.713 | L11: =if(J11>QUARTILE!$B$3, "TOP", if(J11<QUARTILE!$B$4, "BOTTOM", 0)) -> 0 | M11: =if(I11="branch", 1, if(I11="Internet", 2, 3)) -> 2 | N11: =if(B11<16, "Gen Z", if(B11<31, "Millenial", if(B11<61, "Gen X", if(B11<80, "Baby Boomer", "Silent")))) -> Baby Boomer | O11: =if(C11<45000, "Low Income", if(C11<135000, "Medium Income", if(C11<190000, "High Income", "Highest Income"))) -> Low Income
A12: 100010 | B12: 36 | C12: 62000 | D12: NSW | E12: 12178.59 | F12: 1 | G12: 12 | H12: 5 | I12: Internet | J12: 0.915 | K12: 0.825 | L12: =if(J12>QUARTILE!$B$3, "TOP", if(J12<QUARTILE!$B$4, "BOTTOM", 0)) -> TOP | M12: =if(I12="branch", 1, if(I12="Internet", 2, 3)) -> 2 | N12: =if(B12<16, "Gen Z", if(B12<31, "Millenial", if(B12<61, "Gen X", if(B12<80, "Baby Boomer", "Silent")))) -> Gen X | O12: =if(C12<45000, "Low Income", if(C12<135000, "Medium Income", if(C12<190000, "High Income", "Highest Income"))) -> Medium Income
A13: 100011 | B13: 40 | C13: 33000 | D13: VIC | E13: 787.01 | F13: 2 | G13: 20 | H13: 13 | I13: Internet | J13: 0.693 | K13: 0.428 | L13: =if(J13>QUARTILE!$B$3, "TOP", if(J13<QUARTILE!$B$4, "BOTTOM", 0)) -> 0 | M13: =if(I13="branch", 1, if(I13="Internet", 2, 3)) -> 2 | N13: =if(B13<16, "Gen Z", if(B13<31, "Millenial", if(B13<61, "Gen X", if(B13<80, "Baby Boomer", "Silent")))) -> Gen X | O13: =if(C13<45000, "Low Income", if(C13<135000, "Medium Income", if(C13<190000, "High Income", "Highest Income"))) -> Low Income
... A5001: 104999 | B5001: 57 | C5001: 25000 | D5001: NSW | E5001: 3527.04 | F5001: 2 | G5001: 22 | H5001: 2 | I5001: Internet | J5001: 0.406 | K5001: 0.935 | L5001: =if(J5001>QUARTILE!$B$3, "TOP", if(J5001<QUARTILE!$B$4, "BOTTOM", 0)) -> 0 | M5001: =if(I5001="branch", 1, if(I5001="Internet", 2, 3)) -> 2 | N5001: =if(B5001<16, "Gen Z", if(B5001<31, "Millenial", if(B5001<61, "Gen X", if(B5001<80, "Baby Boomer", "Silent")))) -> Gen X | O5001: =if(C5001<45000, "Low Income", if(C5001<135000, "Medium Income", if(C5001<190000, "High Income", "Highest Income"))) -> Low Income

Sheet InvestLab Cohort
A1: customer_id | B1: age | C1: income | D1: region | E1: total_balance | F1: num_products | G1: monthly_transactions | H1: digital_logins_month | I1: preferred_channel | J1: product_interest_score | K1: churn_risk_score | L1: QUARTILE | M1: Preferred Channel | N1: Age Bucket | O1: Income Bucket
A2: 100000 | B2: 56 | C2: 25000 | D2: WA | E2: 47556.32 | F2: 2 | G2: 23 | H2: 2 | I2: Branch | J2: 0.191 | K2: 0.677 | L2: =if(J2>QUARTILE!$B$3, "TOP", if(J2<QUARTILE!$B$4, "BOTTOM", 0)) -> BOTTOM | M2: =if(I2="branch", 1, if(I2="Internet", 2, 3)) -> 1 | N2: =if(B2<16, "Gen Z", if(B2<31, "Millenial", if(B2<61, "Gen X", if(B2<80, "Baby Boomer", "Silent")))) -> Gen X | O2: =if(C2<45000, "Low Income", if(C2<135000, "Medium Income", if(C2<190000, "High Income", "Highest Income"))) -> Low Income
A3: 100001 | B3: 69 | C3: 24000 | D3: SA | E3: 6129.6 | F3: 2 | G3: 26 | H3: 4 | I3: Internet | J3: 0.909 | K3: 0.711 | L3: =if(J3>QUARTILE!$B$3, "TOP", if(J3<QUARTILE!$B$4, "BOTTOM", 0)) -> TOP | M3: =if(I3="branch", 1, if(I3="Internet", 2, 3)) -> 2 | N3: =if(B3<16, "Gen Z", if(B3<31, "Millenial", if(B3<61, "Gen X", if(B3<80, "Baby Boomer", "Silent")))) -> Baby Boomer | O3: =if(C3<45000, "Low Income", if(C3<135000, "Medium Income", if(C3<190000, "High Income", "Highest Income"))) -> Low Income
A4: 100002 | B4: 46 | C4: 15000 | D4: NSW | E4: 6597.25 | F4: 2 | G4: 15 | H4: 8 | I4: Internet | J4: 0.824 | K4: 0.551 | L4: =if(J4>QUARTILE!$B$3, "TOP", if(J4<QUARTILE!$B$4, "BOTTOM", 0)) -> TOP | M4: =if(I4="branch", 1, if(I4="Internet", 2, 3)) -> 2 | N4: =if(B4<16, "Gen Z", if(B4<31, "Millenial", if(B4<61, "Gen X", if(B4<80, "Baby Boomer", "Silent")))) -> Gen X | O4: =if(C4<45000, "Low Income", if(C4<135000, "Medium Income", if(C4<190000, "High Income", "Highest Income"))) -> Low Income
A5: 100003 | B5: 32 | C5: 27000 | D5: WA | E5: 10653 | F5: 2 | G5: 24 | H5: 5 | I5: Internet | J5: 0.552 | K5: 0.889 | L5: =if(J5>QUARTILE!$B$3, "TOP", if(J5<QUARTILE!$B$4, "BOTTOM", 0)) -> 0 | M5: =if(I5="branch", 1, if(I5="Internet", 2, 3)) -> 2 | N5: =if(B5<16, "Gen Z", if(B5<31, "Millenial", if(B5<61, "Gen X", if(B5<80, "Baby Boomer", "Silent")))) -> Gen X | O5: =if(C5<45000, "Low Income", if(C5<135000, "Medium Income", if(C5<190000, "High Income", "Highest Income"))) -> Low Income
A6: 100004 | B6: 60 | C6: 55000 | D6: TAS | E6: 3003.4 | F6: 3 | G6: 21 | H6: 2 | I6: Internet | J6: 0.565 | K6: 0.346 | L6: =if(J6>QUARTILE!$B$3, "TOP", if(J6<QUARTILE!$B$4, "BOTTOM", 0)) -> 0 | M6: =if(I6="branch", 1, if(I6="Internet", 2, 3)) -> 2 | N6: =if(B6<16, "Gen Z", if(B6<31, "Millenial", if(B6<61, "Gen X", if(B6<80, "Baby Boomer", "Silent")))) -> Gen X | O6: =if(C6<45000, "Low Income", if(C6<135000, "Medium Income", if(C6<190000, "High Income", "Highest Income"))) -> Medium Income
A7: 100005 | B7: 25 | C7: 15000 | D7: TAS | E7: 14155.99 | F7: 5 | G7: 17 | H7: 12 | I7: Branch | J7: 0.468 | K7: 0.008 | L7: =if(J7>QUARTILE!$B$3, "TOP", if(J7<QUARTILE!$B$4, "BOTTOM", 0)) -> 0 | M7: =if(I7="branch", 1, if(I7="Internet", 2, 3)) -> 1 | N7: =if(B7<16, "Gen Z", if(B7<31, "Millenial", if(B7<61, "Gen X", if(B7<80, "Baby Boomer", "Silent")))) -> Millenial | O7: =if(C7<45000, "Low Income", if(C7<135000, "Medium Income", if(C7<190000, "High Income", "Highest Income"))) -> Low Income
A8: 100006 | B8: 78 | C8: 39000 | D8: SA | E8: 21874.39 | F8: 2 | G8: 18 | H8: 5 | I8: Internet | J8: 0.616 | K8: 0.376 | L8: =if(J8>QUARTILE!$B$3, "TOP", if(J8<QUARTILE!$B$4, "BOTTOM", 0)) -> 0 | M8: =if(I8="branch", 1, if(I8="Internet", 2, 3)) -> 2 | N8: =if(B8<16, "Gen Z", if(B8<31, "Millenial", if(B8<61, "Gen X", if(B8<80, "Baby Boomer", "Silent")))) -> Baby Boomer | O8: =if(C8<45000, "Low Income", if(C8<135000, "Medium Income", if(C8<190000, "High Income", "Highest Income"))) -> Low Income
A9: 100007 | B9: 38 | C9: 11000 | D9: VIC | E9: 30835.63 | F9: 2 | G9: 16 | H9: 6 | I9: Branch | J9: 0.695 | K9: 0.775 | L9: =if(J9>QUARTILE!$B$3, "TOP", if(J9<QUARTILE!$B$4, "BOTTOM", 0)) -> 0 | M9: =if(I9="branch", 1, if(I9="Internet", 2, 3)) -> 1 | N9: =if(B9<16, "Gen Z", if(B9<31, "Millenial", if(B9<61, "Gen X", if(B9<80, "Baby Boomer", "Silent")))) -> Gen X | O9: =if(C9<45000, "Low Income", if(C9<135000, "Medium Income", if(C9<190000, "High Income", "Highest Income"))) -> Low Income
A10: 100008 | B10: 56 | C10: 78000 | D10: VIC | E10: 24858.03 | F10: 2 | G10: 14 | H10: 5 | I10: Internet | J10: 0.632 | K10: 0.077 | L10: =if(J10>QUARTILE!$B$3, "TOP", if(J10<QUARTILE!$B$4, "BOTTOM", 0)) -> 0 | M10: =if(I10="branch", 1, if(I10="Internet", 2, 3)) -> 2 | N10: =if(B10<16, "Gen Z", if(B10<31, "Millenial", if(B10<61, "Gen X", if(B10<80, "Baby Boomer", "Silent")))) -> Gen X | O10: =if(C10<45000, "Low Income", if(C10<135000, "Medium Income", if(C10<190000, "High Income", "Highest Income"))) -> Medium Income
A11: 100009 | B11: 75 | C11: 35000 | D11: NSW | E11: 3194.83 | F11: 5 | G11: 17 | H11: 2 | I11: Internet | J11: 0.729 | K11: 0.713 | L11: =if(J11>QUARTILE!$B$3, "TOP", if(J11<QUARTILE!$B$4, "BOTTOM", 0)) -> 0 | M11: =if(I11="branch", 1, if(I11="Internet", 2, 3)) -> 2 | N11: =if(B11<16, "Gen Z", if(B11<31, "Millenial", if(B11<61, "Gen X", if(B11<80, "Baby Boomer", "Silent")))) -> Baby Boomer | O11: =if(C11<45000, "Low Income", if(C11<135000, "Medium Income", if(C11<190000, "High Income", "Highest Income"))) -> Low Income
A12: 100010 | B12: 36 | C12: 62000 | D12: NSW | E12: 12178.59 | F12: 1 | G12: 12 | H12: 5 | I12: Internet | J12: 0.915 | K12: 0.825 | L12: =if(J12>QUARTILE!$B$3, "TOP", if(J12<QUARTILE!$B$4, "BOTTOM", 0)) -> TOP | M12: =if(I12="branch", 1, if(I12="Internet", 2, 3)) -> 2 | N12: =if(B12<16, "Gen Z", if(B12<31, "Millenial", if(B12<61, "Gen X", if(B12<80, "Baby Boomer", "Silent")))) -> Gen X | O12: =if(C12<45000, "Low Income", if(C12<135000, "Medium Income", if(C12<190000, "High Income", "Highest Income"))) -> Medium Income
A13: 100011 | B13: 40 | C13: 33000 | D13: VIC | E13: 787.01 | F13: 2 | G13: 20 | H13: 13 | I13: Internet | J13: 0.693 | K13: 0.428 | L13: =if(J13>QUARTILE!$B$3, "TOP", if(J13<QUARTILE!$B$4, "BOTTOM", 0)) -> 0 | M13: =if(I13="branch", 1, if(I13="Internet", 2, 3)) -> 2 | N13: =if(B13<16, "Gen Z", if(B13<31, "Millenial", if(B13<61, "Gen X", if(B13<80, "Baby Boomer", "Silent")))) -> Gen X | O13: =if(C13<45000, "Low Income", if(C13<135000, "Medium Income", if(C13<190000, "High Income", "Highest Income"))) -> Low Income
... A5001: 104999 | B5001: 57 | C5001: 25000 | D5001: NSW | E5001: 3527.04 | F5001: 2 | G5001: 22 | H5001: 2 | I5001: Internet | J5001: 0.406 | K5001: 0.935 | L5001: =if(J5001>QUARTILE!$B$3, "TOP", if(J5001<QUARTILE!$B$4, "BOTTOM", 0)) -> 0 | M5001: =if(I5001="branch", 1, if(I5001="Internet", 2, 3)) -> 2 | N5001: =if(B5001<16, "Gen Z", if(B5001<31, "Millenial", if(B5001<61, "Gen X", if(B5001<80, "Baby Boomer", "Silent")))) -> Gen X | O5001: =if(C5001<45000, "Low Income", if(C5001<135000, "Medium Income", if(C5001<190000, "High Income", "Highest Income"))) -> Low Income

Sheet Sheet19
A1: product_interest_score | B1: total_balance | C1: age | E1: TQ_product_interest_score | F1: TQ_total_balance
A2: 0.191 | B2: 47556.32 | C2: 56 | E2: 0.909 | F2: 6129.6
A3: 0.909 | B3: 6129.6 | C3: 69 | E3: 0.824 | F3: 6597.25
A4: 0.824 | B4: 6597.25 | C4: 46 | E4: 0.915 | F4: 12178.59
A5: 0.552 | B5: 10653 | C5: 32 | E5: 0.893 | F5: 988.93
A6: 0.565 | B6: 3003.4 | C6: 60 | E6: 0.926 | F6: 14720.45
A7: 0.468 | B7: 14155.99 | C7: 25 | E7: 1 | F7: 25486.57
A8: 0.616 | B8: 21874.39 | C8: 78 | E8: 0.901 | F8: 24207.26
A9: 0.695 | B9: 30835.63 | C9: 38 | E9: 0.844 | F9: 24750.32
A10: 0.632 | B10: 24858.03 | C10: 56 | E10: 0.883 | F10: 17455.09
A11: 0.729 | B11: 3194.83 | C11: 75 | E11: 0.841 | F11: 4415.64
A12: 0.915 | B12: 12178.59 | C12: 36 | E12: 0.901 | F12: 54406.43
A13: 0.693 | B13: 787.01 | C13: 40 | E13: 0.996 | F13: 2190.7
... A1245: 0.068 | B1245: 3879.73 | C1245: 63 | E1245: 1 | F1245: 10308.48
A1246: 0.379 | B1246: 10498.86 | C1246: 60
A1247: 0.247 | B1247: 2367.49 | C1247: 64
A1248: 0.67 | B1248: 11633.36 | C1248: 77
A1249: 0.607 | B1249: 8735.11 | C1249: 62
A1250: 0.173 | B1250: 5054.41 | C1250: 35
A1251: 0.506 | B1251: 20554.47 | C1251: 75
A1252: 1 | B1252: 60282.6 | C1252: 55
A1253: 0.461 | B1253: 4641.5 | C1253: 52
A1254: 0.87 | B1254: 24881.38 | C1254: 68
A1255: 0.525 | B1255: 27125.46 | C1255: 32
A1256: 0.808 | B1256: 13787.91 | C1256: 42
A1257: 0.936 | B1257: 45590.72 | C1257: 72
... A5001: 0.406 | B5001: 3527.04 | C5001: 57

Sheet Sources
A1: Age Ranges | B1: https://www.beresfordresearch.com/age-range-by-generation/
A2: Income | B2: https://www.ato.gov.au/tax-rates-and-codes/tax-rates-australian-residents

Sheet Distribution Explore

Sheet Age
A1: ='CBA Digital Banking Case Study '!B1 -> age | B1: Age Bucket | C1: FREQUENCY | D1: Interest Score
A2: ='CBA Digital Banking Case Study '!B2 -> 56 | B2: 19 | C2: {=FREQUENCY(A2:A5001, B2:B11)} -> 157 | D2: 0.56
A3: ='CBA Digital Banking Case Study '!B3 -> 69 | B3: 29 | C3: 772 | D3: 0.57
A4: ='CBA Digital Banking Case Study '!B4 -> 46 | B4: 39 | C4: 769 | D4: 0.57
A5: ='CBA Digital Banking Case Study '!B5 -> 32 | B5: 49 | C5: 794 | D5: 0.56
A6: ='CBA Digital Banking Case Study '!B6 -> 60 | B6: 59 | C6: 818 | D6: 0.56
A7: ='CBA Digital Banking Case Study '!B7 -> 25 | B7: 69 | C7: 793 | D7: 0.55
A8: ='CBA Digital Banking Case Study '!B8 -> 78 | B8: 79 | C8: 814 | D8: 0.56
A9: ='CBA Digital Banking Case Study '!B9 -> 38 | B9: 80 | C9: 83 | D9: 0.58
A10: ='CBA Digital Banking Case Study '!B10 -> 56 | C10: 0
A11: ='CBA Digital Banking Case Study '!B11 -> 75
A12: ='CBA Digital Banking Case Study '!B12 -> 36
A13: ='CBA Digital Banking Case Study '!B13 -> 40
A14: ='CBA Digital Banking Case Study '!B14 -> 28
A15: ='CBA Digital Banking Case Study '!B15 -> 28
A16: ='CBA Digital Banking Case Study '!B16 -> 41
A17: ='CBA Digital Banking Case Study '!B17 -> 70
A18: ='CBA Digital Banking Case Study '!B18 -> 53
A19: ='CBA Digital Banking Case Study '!B19 -> 57
A20: ='CBA Digital Banking Case Study '!B20 -> 41
A21: ='CBA Digital Banking Case Study '!B21 -> 20
A22: ='CBA Digital Banking Case Study '!B22 -> 39
... A6000: ='CBA Digital Banking Case Study '!B6000

Sheet Income
A1: Income | B1: Income Bucket | C1: FREQUENCY
A2: ='CBA Digital Banking Case Study '!C2 -> 25000 | B2: 45000 | C2: {=FREQUENCY(A2:A5001, B2:B5)} -> 4418
A3: ='CBA Digital Banking Case Study '!C3 -> 24000 | B3: 135000 | C3: 577
A4: ='CBA Digital Banking Case Study '!C4 -> 15000 | B4: 190000 | C4: 4
A5: ='CBA Digital Banking Case Study '!C5 -> 27000 | B5: 300000 | C5: 1
A6: ='CBA Digital Banking Case Study '!C6 -> 55000 | C6: 0
A7: ='CBA Digital Banking Case Study '!C7 -> 15000
A8: ='CBA Digital Banking Case Study '!C8 -> 39000
A9: ='CBA Digital Banking Case Study '!C9 -> 11000
A10: ='CBA Digital Banking Case Study '!C10 -> 78000
A11: ='CBA Digital Banking Case Study '!C11 -> 35000
A12: ='CBA Digital Banking Case Study '!C12 -> 62000
A13: ='CBA Digital Banking Case Study '!C13 -> 33000
A14: ='CBA Digital Banking Case Study '!C14 -> 28000
A15: ='CBA Digital Banking Case Study '!C15 -> 35000
A16: ='CBA Digital Banking Case Study '!C16 -> 20000
A17: ='CBA Digital Banking Case Study '!C17 -> 8000
A18: ='CBA Digital Banking Case Study '!C18 -> 29000
... A6000: ='CBA Digital Banking Case Study '!C6000

Sheet Region
A1: Region | B1: Region Factor | C1: Region Bucket | D1: FREQUENCY
A2: ='CBA Digital Banking Case Study '!D2 -> WA | B2: =if(A2="WA", 1, if(A2="SA", 2, IF(A2="NSW", 3, IF(A2="TAS", 4, IF(A2="VIC", 5, IF(A2="ACT", 6, if(A2="QLD", 7,8))))))) -> 1 | C2: WA | D2: =COUNTIF($B$2:$B$5001,1) -> 514
A3: ='CBA Digital Banking Case Study '!D3 -> SA | B3: =if(A3="WA", 1, if(A3="SA", 2, IF(A3="NSW", 3, IF(A3="TAS", 4, IF(A3="VIC", 5, IF(A3="ACT", 6, if(A3="QLD", 7,8))))))) -> 2 | C3: SA | D3: =COUNTIF($B$2:$B$5001,2) -> 237
A4: ='CBA Digital Banking Case Study '!D4 -> NSW | B4: =if(A4="WA", 1, if(A4="SA", 2, IF(A4="NSW", 3, IF(A4="TAS", 4, IF(A4="VIC", 5, IF(A4="ACT", 6, if(A4="QLD", 7,8))))))) -> 3 | C4: NSW | D4: =COUNTIF($B$2:$B$5001,3) -> 1589
A5: ='CBA Digital Banking Case Study '!D5 -> WA | B5: =if(A5="WA", 1, if(A5="SA", 2, IF(A5="NSW", 3, IF(A5="TAS", 4, IF(A5="VIC", 5, IF(A5="ACT", 6, if(A5="QLD", 7,8))))))) -> 1 | C5: TAS | D5: =COUNTIF($B$2:$B$5001,4) -> 159
A6: ='CBA Digital Banking Case Study '!D6 -> TAS | B6: =if(A6="WA", 1, if(A6="SA", 2, IF(A6="NSW", 3, IF(A6="TAS", 4, IF(A6="VIC", 5, IF(A6="ACT", 6, if(A6="QLD", 7,8))))))) -> 4 | C6: VIC | D6: =COUNTIF($B$2:$B$5001,5) -> 1317
A7: ='CBA Digital Banking Case Study '!D7 -> TAS | B7: =if(A7="WA", 1, if(A7="SA", 2, IF(A7="NSW", 3, IF(A7="TAS", 4, IF(A7="VIC", 5, IF(A7="ACT", 6, if(A7="QLD", 7,8))))))) -> 4 | C7: ACT | D7: =COUNTIF($B$2:$B$5001,6) -> 141
A8: ='CBA Digital Banking Case Study '!D8 -> SA | B8: =if(A8="WA", 1, if(A8="SA", 2, IF(A8="NSW", 3, IF(A8="TAS", 4, IF(A8="VIC", 5, IF(A8="ACT", 6, if(A8="QLD", 7,8))))))) -> 2 | C8: QLD | D8: =COUNTIF($B$2:$B$5001,7) -> 991
A9: ='CBA Digital Banking Case Study '!D9 -> VIC | B9: =if(A9="WA", 1, if(A9="SA", 2, IF(A9="NSW", 3, IF(A9="TAS", 4, IF(A9="VIC", 5, IF(A9="ACT", 6, if(A9="QLD", 7,8))))))) -> 5 | C9: NT | D9: =COUNTIF($B$2:$B$5001,8) -> 52
A10: ='CBA Digital Banking Case Study '!D10 -> VIC | B10: =if(A10="WA", 1, if(A10="SA", 2, IF(A10="NSW", 3, IF(A10="TAS", 4, IF(A10="VIC", 5, IF(A10="ACT", 6, if(A10="QLD", 7,8))))))) -> 5
A11: ='CBA Digital Banking Case Study '!D11 -> NSW | B11: =if(A11="WA", 1, if(A11="SA", 2, IF(A11="NSW", 3, IF(A11="TAS", 4, IF(A11="VIC", 5, IF(A11="ACT", 6, if(A11="QLD", 7,8))))))) -> 3
A12: ='CBA Digital Banking Case Study '!D12 -> NSW | B12: =if(A12="WA", 1, if(A12="SA", 2, IF(A12="NSW", 3, IF(A12="TAS", 4, IF(A12="VIC", 5, IF(A12="ACT", 6, if(A12="QLD", 7,8))))))) -> 3
A13: ='CBA Digital Banking Case Study '!D13 -> VIC | B13: =if(A13="WA", 1, if(A13="SA", 2, IF(A13="NSW", 3, IF(A13="TAS", 4, IF(A13="VIC", 5, IF(A13="ACT", 6, if(A13="QLD", 7,8))))))) -> 5
A14: ='CBA Digital Banking Case Study '!D14 -> VIC | B14: =if(A14="WA", 1, if(A14="SA", 2, IF(A14="NSW", 3, IF(A14="TAS", 4, IF(A14="VIC", 5, IF(A14="ACT", 6, if(A14="QLD", 7,8))))))) -> 5
A15: ='CBA Digital Banking Case Study '!D15 -> NSW | B15: =if(A15="WA", 1, if(A15="SA", 2, IF(A15="NSW", 3, IF(A15="TAS", 4, IF(A15="VIC", 5, IF(A15="ACT", 6, if(A15="QLD", 7,8))))))) -> 3
A16: ='CBA Digital Banking Case Study '!D16 -> VIC | B16: =if(A16="WA", 1, if(A16="SA", 2, IF(A16="NSW", 3, IF(A16="TAS", 4, IF(A16="VIC", 5, IF(A16="ACT", 6, if(A16="QLD", 7,8))))))) -> 5
A17: ='CBA Digital Banking Case Study '!D17 -> NSW | B17: =if(A17="WA", 1, if(A17="SA", 2, IF(A17="NSW", 3, IF(A17="TAS", 4, IF(A17="VIC", 5, IF(A17="ACT", 6, if(A17="QLD", 7,8))))))) -> 3
A18: ='CBA Digital Banking Case Study '!D18 -> WA | B18: =if(A18="WA", 1, if(A18="SA", 2, IF(A18="NSW", 3, IF(A18="TAS", 4, IF(A18="VIC", 5, IF(A18="ACT", 6, if(A18="QLD", 7,8))))))) -> 1
A19: ='CBA Digital Banking Case Study '!D19 -> NSW | B19: =if(A19="WA", 1, if(A19="SA", 2, IF(A19="NSW", 3, IF(A19="TAS", 4, IF(A19="VIC", 5, IF(A19="ACT", 6, if(A19="QLD", 7,8))))))) -> 3
A20: ='CBA Digital Banking Case Study '!D20 -> QLD | B20: =if(A20="WA", 1, if(A20="SA", 2, IF(A20="NSW", 3, IF(A20="TAS", 4, IF(A20="VIC", 5, IF(A20="ACT", 6, if(A20="QLD", 7,8))))))) -> 7
A21: ='CBA Digital Banking Case Study '!D21 -> VIC | B21: =if(A21="WA", 1, if(A21="SA", 2, IF(A21="NSW", 3, IF(A21="TAS", 4, IF(A21="VIC", 5, IF(A21="ACT", 6, if(A21="QLD", 7,8))))))) -> 5
... A5001: ='CBA Digital Banking Case Study '!D5001 -> NSW | B5001: =if(A5001="WA", 1, if(A5001="SA", 2, IF(A5001="NSW", 3, IF(A5001="TAS", 4, IF(A5001="VIC", 5, IF(A5001="ACT", 6, if(A5001="QLD", 7,8))))))) -> 3
A5002: ='CBA Digital Banking Case Study '!D5002
A5003: ='CBA Digital Banking Case Study '!D5003
A5004: ='CBA Digital Banking Case Study '!D5004
A5005: ='CBA Digital Banking Case Study '!D5005
A5006: ='CBA Digital Banking Case Study '!D5006
A5007: ='CBA Digital Banking Case Study '!D5007
A5008: ='CBA Digital Banking Case Study '!D5008
A5009: ='CBA Digital Banking Case Study '!D5009
A5010: ='CBA Digital Banking Case Study '!D5010
A5011: ='CBA Digital Banking Case Study '!D5011
A5012: ='CBA Digital Banking Case Study '!D5012
A5013: ='CBA Digital Banking Case Study '!D5013
... A6000: ='CBA Digital Banking Case Study '!D6000

Sheet Balance

Sheet QUARTILE
C1: MEDIUM
C2: age | D2: income | E2: region | F2: total_balance | G2: num_products | H2: monthly_transactions | I2: digital_logins_month | J2: preferred_channel
A3: 3rd Quartile | B3: =QUARTILE('CBA Digital Banking Case Study '!J2:J5001, 3) -> 0.816 | C3: =AVERAGE('TOP QUARTILE CUST'!B2:B1245) -> 48.790997 | D3: =AVERAGE('TOP QUARTILE CUST'!C2:C1245) -> 27499.196 | F3: =AVERAGE('TOP QUARTILE CUST'!E2:E1245) -> 22532.779 | G3: =AVERAGE('TOP QUARTILE CUST'!F2:F1245) -> 3.0771704 | H3: =MEDIAN('TOP QUARTILE CUST'!G2:G1245) -> 20 | I3: =MEDIAN('TOP QUARTILE CUST'!H2:H1245) -> 8
A4: 1st Quartile | B4: =QUARTILE('CBA Digital Banking Case Study '!J2:J5002, 1) -> 0.315 | C4: =AVERAGE('BOTTOM QUARTILE CUST'!B2:B1242) -> 49.515713 | D4: =AVERAGE('BOTTOM QUARTILE CUST'!C2:C1242) -> 24950.846 | F4: =AVERAGE('BOTTOM QUARTILE CUST'!E2:E1242) -> 16513.147 | G4: =AVERAGE('BOTTOM QUARTILE CUST'!F2:F1242) -> 3.0523771 | H4: =MEDIAN('BOTTOM QUARTILE CUST'!G2:G1242) -> 20 | I4: =MEDIAN('BOTTOM QUARTILE CUST'!H2:H1242) -> 7

Sheet TOP QUARTILE CUST
A1: customer_id | B1: age | C1: income | D1: region | E1: total_balance | F1: num_products | G1: monthly_transactions | H1: digital_logins_month | I1: preferred_channel | J1: product_interest_score | K1: churn_risk_score | L1: QUARTILE | M1: Pref_Channel | N1: preferred_channel | O1: MEDIAN of product_interest_score | P1: COUNT of customer_id
A2: 100001 | B2: 69 | C2: 24000 | D2: SA | E2: 6129.6 | F2: 2 | G2: 26 | H2: 4 | I2: Internet | J2: 0.909 | K2: 0.711 | L2: =if(J2>QUARTILE!$B$3, "TOP", 0) -> TOP | M2: =if(I2="Branch", 1, if(I2="Internet", 2, 3)) -> 2 | N2: Branch | O2: 0.949 | P2: 431
A3: 100002 | B3: 46 | C3: 15000 | D3: NSW | E3: 6597.25 | F3: 2 | G3: 15 | H3: 8 | I3: Internet | J3: 0.824 | K3: 0.551 | L3: =if(J3>QUARTILE!$B$3, "TOP", 0) -> TOP | M3: =if(I3="Branch", 1, if(I3="Internet", 2, 3)) -> 2 | N3: Internet | O3: 0.934 | P3: 775
A4: 100010 | B4: 36 | C4: 62000 | D4: NSW | E4: 12178.59 | F4: 1 | G4: 12 | H4: 5 | I4: Internet | J4: 0.915 | K4: 0.825 | L4: =if(J4>QUARTILE!$B$3, "TOP", 0) -> TOP | M4: =if(I4="Branch", 1, if(I4="Internet", 2, 3)) -> 2 | N4: Mobile | O4: 0.976 | P4: 38
A5: 100019 | B5: 20 | C5: 32000 | D5: VIC | E5: 988.93 | F5: 4 | G5: 26 | H5: 7 | I5: Internet | J5: 0.893 | K5: 0.924 | L5: =if(J5>QUARTILE!$B$3, "TOP", 0) -> TOP | M5: =if(I5="Branch", 1, if(I5="Internet", 2, 3)) -> 2 | N5: Grand Total | O5: 0.94 | P5: 1244
A6: 100025 | B6: 47 | C6: 26000 | D6: VIC | E6: 14720.45 | F6: 5 | G6: 26 | H6: 11 | I6: Internet | J6: 0.926 | K6: 0.616 | L6: =if(J6>QUARTILE!$B$3, "TOP", 0) -> TOP | M6: =if(I6="Branch", 1, if(I6="Internet", 2, 3)) -> 2
A7: 100026 | B7: 55 | C7: 9000 | D7: NSW | E7: 25486.57 | F7: 2 | G7: 24 | H7: 4 | I7: Internet | J7: 1 | K7: 0.37 | L7: =if(J7>QUARTILE!$B$3, "TOP", 0) -> TOP | M7: =if(I7="Branch", 1, if(I7="Internet", 2, 3)) -> 2
A8: 100027 | B8: 19 | C8: 26000 | D8: VIC | E8: 24207.26 | F8: 5 | G8: 13 | H8: 19 | I8: Internet | J8: 0.901 | K8: 0.181 | L8: =if(J8>QUARTILE!$B$3, "TOP", 0) -> TOP | M8: =if(I8="Branch", 1, if(I8="Internet", 2, 3)) -> 2
A9: 100033 | B9: 39 | C9: 42000 | D9: VIC | E9: 24750.32 | F9: 1 | G9: 25 | H9: 5 | I9: Internet | J9: 0.844 | K9: 0.152 | L9: =if(J9>QUARTILE!$B$3, "TOP", 0) -> TOP | M9: =if(I9="Branch", 1, if(I9="Internet", 2, 3)) -> 2
A10: 100034 | B10: 78 | C10: 25000 | D10: NSW | E10: 17455.09 | F10: 4 | G10: 16 | H10: 5 | I10: Internet | J10: 0.883 | K10: 0.216 | L10: =if(J10>QUARTILE!$B$3, "TOP", 0) -> TOP | M10: =if(I10="Branch", 1, if(I10="Internet", 2, 3)) -> 2
A11: 100035 | B11: 61 | C11: 48000 | D11: NSW | E11: 4415.64 | F11: 2 | G11: 25 | H11: 7 | I11: Internet | J11: 0.841 | K11: 0.997 | L11: =if(J11>QUARTILE!$B$3, "TOP", 0) -> TOP | M11: =if(I11="Branch", 1, if(I11="Internet", 2, 3)) -> 2
A12: 100042 | B12: 45 | C12: 12000 | D12: QLD | E12: 54406.43 | F12: 2 | G12: 27 | H12: 9 | I12: Branch | J12: 0.901 | K12: 0.304 | L12: =if(J12>QUARTILE!$B$3, "TOP", 0) -> TOP | M12: =if(I12="Branch", 1, if(I12="Internet", 2, 3)) -> 1
A13: 100044 | B13: 33 | C13: 25000 | D13: WA | E13: 2190.7 | F13: 3 | G13: 22 | H13: 7 | I13: Internet | J13: 0.996 | K13: 0.296 | L13: =if(J13>QUARTILE!$B$3, "TOP", 0) -> TOP | M13: =if(I13="Branch", 1, if(I13="Internet", 2, 3)) -> 2
A14: 100045 | B14: 32 | C14: 28000 | D14: WA | E14: 8413.91 | F14: 2 | G14: 19 | H14: 6 | I14: Internet | J14: 0.862 | K14: 0.321 | L14: =if(J14>QUARTILE!$B$3, "TOP", 0) -> TOP | M14: =if(I14="Branch", 1, if(I14="Internet", 2, 3)) -> 2
A15: 100046 | B15: 79 | C15: 11000 | D15: QLD | E15: 27402.29 | F15: 5 | G15: 22 | H15: 3 | I15: Internet | J15: 0.956 | K15: 0.826 | L15: =if(J15>QUARTILE!$B$3, "TOP", 0) -> TOP | M15: =if(I15="Branch", 1, if(I15="Internet", 2, 3)) -> 2
A16: 100047 | B16: 79 | C16: 18000 | D16: VIC | E16: 19674.12 | F16: 3 | G16: 23 | H16: 2 | I16: Internet | J16: 0.883 | K16: 0.626 | L16: =if(J16>QUARTILE!$B$3, "TOP", 0) -> TOP | M16: =if(I16="Branch", 1, if(I16="Internet", 2, 3)) -> 2
A17: 100050 | B17: 68 | C17: 13000 | D17: QLD | E17: 26560.24 | F17: 4 | G17: 16 | H17: 6 | I17: Internet | J17: 0.908 | K17: 0 | L17: =if(J17>QUARTILE!$B$3, "TOP", 0) -> TOP | M17: =if(I17="Branch", 1, if(I17="Internet", 2, 3)) -> 2
... A1245: 104994 | B1245: 54 | C1245: 40000 | D1245: VIC | E1245: 10308.48 | F1245: 5 | G1245: 22 | H1245: 6 | I1245: Internet | J1245: 1 | K1245: 0.163 | L1245: =if(J1245>QUARTILE!$B$3, "TOP", 0) -> TOP | M1245: =if(I1245="Branch", 1, if(I1245="Internet", 2, 3)) -> 2

Sheet BOTTOM QUARTILE CUST
A1: customer_id | B1: age | C1: income | D1: region | E1: total_balance | F1: num_products | G1: monthly_transactions | H1: digital_logins_month | I1: preferred_channel | J1: product_interest_score | K1: churn_risk_score | L1: QUARTILE | M1: Pref_Channel
A2: 100000 | B2: 56 | C2: 25000 | D2: WA | E2: 47556.32 | F2: 2 | G2: 23 | H2: 2 | I2: Branch | J2: 0.191 | K2: 0.677 | L2: =if(J2>QUARTILE!$B$3, "TOP", if(J2<QUARTILE!$B$4, "BOTTOM", 0)) -> BOTTOM | M2: =if(I2="Branch", 1, if(I2="Internet", 2, 3)) -> 1 | N2: preferred_channel | O2: MEDIAN of product_interest_score | P2: COUNT of customer_id
A3: 100014 | B3: 41 | C3: 20000 | D3: VIC | E3: 5832.74 | F3: 1 | G3: 21 | H3: 11 | I3: Branch | J3: 0.149 | K3: 0.398 | L3: =if(J3>QUARTILE!$B$3, "TOP", if(J3<QUARTILE!$B$4, "BOTTOM", 0)) -> BOTTOM | M3: =if(I3="Branch", 1, if(I3="Internet", 2, 3)) -> 1 | N3: Branch | O3: 0.199 | P3: 297
A4: 100017 | B4: 57 | C4: 14000 | D4: NSW | E4: 45152.95 | F4: 1 | G4: 23 | H4: 3 | I4: Branch | J4: 0.216 | K4: 0.873 | L4: =if(J4>QUARTILE!$B$3, "TOP", if(J4<QUARTILE!$B$4, "BOTTOM", 0)) -> BOTTOM | M4: =if(I4="Branch", 1, if(I4="Internet", 2, 3)) -> 1 | N4: Internet | O4: 0.1795 | P4: 940
A5: 100018 | B5: 41 | C5: 11000 | D5: QLD | E5: 28599.28 | F5: 4 | G5: 25 | H5: 12 | I5: Branch | J5: 0.176 | K5: 0.059 | L5: =if(J5>QUARTILE!$B$3, "TOP", if(J5<QUARTILE!$B$4, "BOTTOM", 0)) -> BOTTOM | M5: =if(I5="Branch", 1, if(I5="Internet", 2, 3)) -> 1 | N5: Mobile | O5: 0.285 | P5: 4
A6: 100028 | B6: 77 | C6: 54000 | D6: VIC | E6: 11991.11 | F6: 5 | G6: 17 | H6: 5 | I6: Internet | J6: 0.217 | K6: 0.945 | L6: =if(J6>QUARTILE!$B$3, "TOP", if(J6<QUARTILE!$B$4, "BOTTOM", 0)) -> BOTTOM | M6: =if(I6="Branch", 1, if(I6="Internet", 2, 3)) -> 2 | N6: Grand Total | O6: 0.185 | P6: 1241
A7: 100041 | B7: 59 | C7: 12000 | D7: QLD | E7: 9532.48 | F7: 3 | G7: 17 | H7: 9 | I7: Internet | J7: 0.055 | K7: 0.581 | L7: =if(J7>QUARTILE!$B$3, "TOP", if(J7<QUARTILE!$B$4, "BOTTOM", 0)) -> BOTTOM | M7: =if(I7="Branch", 1, if(I7="Internet", 2, 3)) -> 2
A8: 100043 | B8: 77 | C8: 24000 | D8: NSW | E8: 4790.87 | F8: 3 | G8: 14 | H8: 6 | I8: Internet | J8: 0.113 | K8: 0.936 | L8: =if(J8>QUARTILE!$B$3, "TOP", if(J8<QUARTILE!$B$4, "BOTTOM", 0)) -> BOTTOM | M8: =if(I8="Branch", 1, if(I8="Internet", 2, 3)) -> 2
A9: 100048 | B9: 64 | C9: 12000 | D9: QLD | E9: 10750.08 | F9: 3 | G9: 16 | H9: 6 | I9: Internet | J9: 0.101 | K9: 0.951 | L9: =if(J9>QUARTILE!$B$3, "TOP", if(J9<QUARTILE!$B$4, "BOTTOM", 0)) -> BOTTOM | M9: =if(I9="Branch", 1, if(I9="Internet", 2, 3)) -> 2
A10: 100051 | B10: 61 | C10: 19000 | D10: WA | E10: 1277.15 | F10: 3 | G10: 16 | H10: 6 | I10: Internet | J10: 0.091 | K10: 0.177 | L10: =if(J10>QUARTILE!$B$3, "TOP", if(J10<QUARTILE!$B$4, "BOTTOM", 0)) -> BOTTOM | M10: =if(I10="Branch", 1, if(I10="Internet", 2, 3)) -> 2
A11: 100057 | B11: 68 | C11: 38000 | D11: NSW | E11: 7414.89 | F11: 2 | G11: 17 | H11: 4 | I11: Internet | J11: 0.289 | K11: 0.139 | L11: =if(J11>QUARTILE!$B$3, "TOP", if(J11<QUARTILE!$B$4, "BOTTOM", 0)) -> BOTTOM | M11: =if(I11="Branch", 1, if(I11="Internet", 2, 3)) -> 2
A12: 100067 | B12: 67 | C12: 29000 | D12: WA | E12: 21103.3 | F12: 2 | G12: 16 | H12: 5 | I12: Internet | J12: 0.123 | K12: 0.638 | L12: =if(J12>QUARTILE!$B$3, "TOP", if(J12<QUARTILE!$B$4, "BOTTOM", 0)) -> BOTTOM | M12: =if(I12="Branch", 1, if(I12="Internet", 2, 3)) -> 2
A13: 100070 | B13: 43 | C13: 29000 | D13: WA | E13: 63867.74 | F13: 3 | G13: 18 | H13: 10 | I13: Branch | J13: 0.258 | K13: 0.305 | L13: =if(J13>QUARTILE!$B$3, "TOP", if(J13<QUARTILE!$B$4, "BOTTOM", 0)) -> BOTTOM | M13: =if(I13="Branch", 1, if(I13="Internet", 2, 3)) -> 1
A14: 100071 | B14: 70 | C14: 38000 | D14: ACT | E14: 8445.35 | F14: 2 | G14: 15 | H14: 3 | I14: Internet | J14: 0.23 | K14: 0.589 | L14: =if(J14>QUARTILE!$B$3, "TOP", if(J14<QUARTILE!$B$4, "BOTTOM", 0)) -> BOTTOM | M14: =if(I14="Branch", 1, if(I14="Internet", 2, 3)) -> 2
A15: 100072 | B15: 19 | C15: 17000 | D15: VIC | E15: 4208.96 | F15: 3 | G15: 26 | H15: 19 | I15: Branch | J15: 0.171 | K15: 0.97 | L15: =if(J15>QUARTILE!$B$3, "TOP", if(J15<QUARTILE!$B$4, "BOTTOM", 0)) -> BOTTOM | M15: =if(I15="Branch", 1, if(I15="Internet", 2, 3)) -> 1
A16: 100074 | B16: 45 | C16: 20000 | D16: VIC | E16: 24273.68 | F16: 4 | G16: 17 | H16: 17 | I16: Branch | J16: 0.121 | K16: 0.184 | L16: =if(J16>QUARTILE!$B$3, "TOP", if(J16<QUARTILE!$B$4, "BOTTOM", 0)) -> BOTTOM | M16: =if(I16="Branch", 1, if(I16="Internet", 2, 3)) -> 1
A17: 100077 | B17: 24 | C17: 17000 | D17: QLD | E17: 25118.79 | F17: 4 | G17: 22 | H17: 24 | I17: Mobile | J17: 0.281 | K17: 0.843 | L17: =if(J17>QUARTILE!$B$3, "TOP", if(J17<QUARTILE!$B$4, "BOTTOM", 0)) -> BOTTOM | M17: =if(I17="Branch", 1, if(I17="Internet", 2, 3)) -> 3
A18: 100079 | B18: 78 | C18: 24000 | D18: NSW | E18: 49820.61 | F18: 1 | G18: 17 | H18: 4 | I18: Branch | J18: 0.15 | K18: 0.334 | L18: =if(J18>QUARTILE!$B$3, "TOP", if(J18<QUARTILE!$B$4, "BOTTOM", 0)) -> BOTTOM | M18: =if(I18="Branch", 1, if(I18="Internet", 2, 3)) -> 1
... A1242: 104993 | B1242: 42 | C1242: 10000 | D1242: VIC | E1242: 16049.29 | F1242: 3 | G1242: 23 | H1242: 13 | I1242: Internet | J1242: 0.116 | K1242: 0.501 | L1242: =if(J1242>QUARTILE!$B$3, "TOP", if(J1242<QUARTILE!$B$4, "BOTTOM", 0)) -> BOTTOM | M1242: =if(I1242="Branch", 1, if(I1242="Internet", 2, 3)) -> 2

Sheet RawPivot

Sheet Master Charts
B2: Branch Preference
B3: QUARTILE | C3: Branch | D3: Internet | E3: Mobile | F3: Grand Total
B4: BOTTOM | C4: 297 | D4: 940 | E4: 4 | F4: 1241
B5: TOP | C5: 431 | D5: 775 | E5: 38 | F5: 1244
B6: ALL | C6: 1457 | D6: 3465 | E6: 78 | F6: 5000
B8: QUARTILE | C8: Branch | D8: Internet | E8: Mobile | F8: Grand Total
B9: BOTTOM | C9: =C4/$F4 -> 0.23932313 | D9: =D4/$F4 -> 0.75745367 | E9: =E4/$F4 -> 0.0032232071 | F9: =F4/$F4 -> 1
B10: TOP | C10: =C5/$F5 -> 0.34646302 | D10: =D5/$F5 -> 0.62299035 | E10: =E5/$F5 -> 0.030546624 | F10: =F5/$F5 -> 1
B11: ALL | C11: =C6/$F6 -> 0.2914 | D11: =D6/$F6 -> 0.693 | E11: =E6/$F6 -> 0.0156 | F11: =F6/$F6 -> 1
B13: Age Breakdown
B14: QUARTILE | C14: Baby Boomer | D14: Gen X | E14: Millenial | F14: Silent | G14: Grand Total
B15: BOTTOM | C15: 395 | D15: 586 | E15: 246 | F15: 14 | G15: 1241
B16: TOP | C16: 377 | D16: 591 | E16: 260 | F16: 16 | G16: 1244
B17: ALL | C17: 1549 | D17: 2368 | E17: 1000 | F17: 83 | G17: =SUM(C17:F17) -> 5000
B19: QUARTILE | C19: Baby Boomer | D19: Gen X | E19: Millenial | F19: Silent | G19: Grand Total
B20: BOTTOM | C20: =C15/$G15 -> 0.3182917 | D20: =D15/$G15 -> 0.47219984 | E20: =E15/$G15 -> 0.19822724 | F20: =F15/$G15 -> 0.011281225 | G20: =G15/$G15 -> 1
B21: TOP | C21: =C16/$G16 -> 0.30305466 | D21: =D16/$G16 -> 0.47508039 | E21: =E16/$G16 -> 0.20900322 | F21: =F16/$G16 -> 0.012861736 | G21: =G16/$G16 -> 1
B22: ALL | C22: =C17/$G17 -> 0.3098 | D22: =D17/$G17 -> 0.4736 | E22: =E17/$G17 -> 0.2 | F22: =F17/$G17 -> 0.0166 | G22: =G17/$G17 -> 1
B25: Income Breakdown
B26: QUARTILE | C26: High Income | D26: Highest Income | E26: Low Income | F26: Medium Income | G26: Grand Total
B27: BOTTOM | E27: 1133 | F27: 108 | G27: 1241
B28: TOP | C28: 2 | E28: 1061 | F28: 181 | G28: 1244
B29: ALL | C29: 4 | D29: 1 | E29: 4390 | F29: 605 | G29: 5000
B31: QUARTILE | C31: High Income | D31: Highest Income | E31: Low Income | F31: Medium Income | G31: Grand Total
B32: BOTTOM | C32: =C27/$G27 -> 0 | D32: =D27/$G27 -> 0 | E32: =E27/$G27 -> 0.91297341 | F32: =F27/$G27 -> 0.087026591 | G32: =G27/$G27 -> 1
B33: TOP | C33: =C28/$G28 -> 0.001607717 | D33: =D28/$G28 -> 0 | E33: =E28/$G28 -> 0.85289389 | F33: =F28/$G28 -> 0.14549839 | G33: =G28/$G28 -> 1
B34: ALL | C34: =C29/$G29 -> 0.0008 | D34: =D29/$G29 -> 0.0002 | E34: =E29/$G29 -> 0.878 | F34: =F29/$G29 -> 0.121 | G34: =G29/$G29 -> 1
B36: Total Balance
B37: QUARTILE | C37: MEDIAN of total_balance
B38: BOTTOM | C38: 11801.92
B39: TOP | C39: 16298.635
B40: ALL | C40: 13565.215
B42: Number of Products
B43: QUARTILE | C43: MEDIAN of num_products
B44: BOTTOM | C44: 3
B45: TOP | C45: 3
B46: ALL | C46: 3
B48: Monthly Transactions
B49: QUARTILE | C49: MEDIAN of monthly_transactions
B50: BOTTOM | C50: 20
...

Sheet CORRELATION
B1: Age | C1: Income | D1: Total Balance | E1: Number of Products | F1: Monthly Txns | G1: Digital Logins (Monthly) | H1: Preferred Channel | I1: Churn
A2: R-Score ALL | B2: =CORREL('CBA Digital Banking Case Study '!J2:J5001, 'CBA Digital Banking Case Study '!B2:B5001) -> -0.0096416437 | C2: =CORREL('CBA Digital Banking Case Study '!J2:J5001, 'CBA Digital Banking Case Study '!C2:C5001) -> 0.053221958 | D2: =CORREL('CBA Digital Banking Case Study '!J2:J5001, 'CBA Digital Banking Case Study '!E2:E5001) -> 0.11913231 | E2: =CORREL('CBA Digital Banking Case Study '!J2:J5001, 'CBA Digital Banking Case Study '!F2:F5001) -> 0.010608107 | F2: =CORREL('CBA Digital Banking Case Study '!J2:J5001, 'CBA Digital Banking Case Study '!G2:G5001) -> -0.003307257 | G2: =CORREL('CBA Digital Banking Case Study '!J2:J5001, 'CBA Digital Banking Case Study '!H2:H5001) -> 0.01642525 | H2: =CORREL('CBA Digital Banking Case Study '!J2:J5001, 'CBA Digital Banking Case Study '!M2:M5001) -> -0.059382807 | I2: =CORREL('CBA Digital Banking Case Study '!J2:J5001,'CBA Digital Banking Case Study '!K2:K5001) -> -0.015914923
A3: R-Score TOP | B3: =CORREL('TOP QUARTILE CUST'!J2:J1245, 'TOP QUARTILE CUST'!B2:B1245) -> 0.0027249147 | C3: =CORREL('TOP QUARTILE CUST'!K2:K1245, 'TOP QUARTILE CUST'!C2:C1245) -> 0.011151185 | D3: =correl('TOP QUARTILE CUST'!J2:J1245,'TOP QUARTILE CUST'!E2:E1245) -> 0.13828474 | E3: =correl('TOP QUARTILE CUST'!J2:J1245, 'TOP QUARTILE CUST'!F2:F1245) -> 0.044639864 | F3: =CORREL('TOP QUARTILE CUST'!K2:K1245, 'TOP QUARTILE CUST'!G2:G1245) -> -0.0011870198 | G3: =correl('TOP QUARTILE CUST'!J2:J1245, 'TOP QUARTILE CUST'!H2:H1245) -> 0.0079652823 | H3: =CORREL('CBA Digital Banking Case Study '!J3:J5002, 'CBA Digital Banking Case Study '!M3:M5002) -> -0.059793561 | I3: =correl('TOP QUARTILE CUST'!J2:J1245,'TOP QUARTILE CUST'!K2:K1245) -> -0.014491969
A4: R-Score BOTTOM | B4: =CORREL('BOTTOM QUARTILE CUST'!J2:J1242, 'BOTTOM QUARTILE CUST'!B2:B1242) -> 0.028784499 | C4: =correl('BOTTOM QUARTILE CUST'!J2:J1242, 'BOTTOM QUARTILE CUST'!C2:C1242) -> 0.12192405 | D4: =correl('BOTTOM QUARTILE CUST'!J2:J1242, 'BOTTOM QUARTILE CUST'!E2:E1242) -> 0.18481741 | E4: =correl('BOTTOM QUARTILE CUST'!J2:J1242, 'BOTTOM QUARTILE CUST'!F2:F1242) -> -0.0053463682 | F4: =correl('BOTTOM QUARTILE CUST'!J2:J1242, 'BOTTOM QUARTILE CUST'!G2:G1242) -> -0.00865051 | G4: =correl('BOTTOM QUARTILE CUST'!J2:J1242, 'BOTTOM QUARTILE CUST'!H2:H1242) -> -0.015422031 | H4: =correl('BOTTOM QUARTILE CUST'!J2:J1242,'BOTTOM QUARTILE CUST'!M2:M1242) -> -0.079726752 | I4: =CORREL('BOTTOM QUARTILE CUST'!J2:J1242,'BOTTOM QUARTILE CUST'!K2:K1242) -> -0.021413972
